<?xml version="1.0"?>
<robot name="simple_arm">

  <!-- 基座 link -->
  <link name="base_link">
    <visual>
      <geometry>
        <cylinder radius="0.1" length="0.05"/>
      </geometry>
      <material name="grey">
        <color rgba="0.5 0.5 0.5 1.0"/>
      </material>
    </visual>
  </link>

  <!-- 上臂 link -->
  <link name="upper_arm">
    <visual>
      <origin xyz="0 0 0.25" rpy="0 0 0"/>
      <geometry>
        <box size="0.05 0.05 0.5"/>
      </geometry>
      <material name="blue">
        <color rgba="0.0 0.0 0.8 1.0"/>
      </material>
    </visual>
  </link>

  <!-- 下臂 link -->
  <link name="lower_arm">
    <visual>
      <origin xyz="0 0 0.15" rpy="0 0 0"/>
      <geometry>
        <box size="0.04 0.04 0.3"/>
      </geometry>
      <material name="red">
        <color rgba="0.8 0.0 0.0 1.0"/>
      </material>
    </visual>
  </link>

  <!-- 基座到上臂的旋转关节 -->
  <joint name="base_to_upper" type="revolute">
    <parent link="base_link"/>
    <child link="upper_arm"/>
    <origin xyz="0 0 0.025" rpy="0 0 0"/>
    <axis xyz="0 1 0"/>
    <limit lower="-1.57" upper="1.57" effort="100.0" velocity="1.0"/>
  </joint>

  <!-- 上臂到下臂的固定关节 -->
  <joint name="upper_to_lower" type="fixed">
    <parent link="upper_arm"/>
    <child link="lower_arm"/>
    <origin xyz="0 0 0.5" rpy="0 0 0"/>
  </joint>

</robot>
