<?xml version="1.0"?>
<robot name="simple_robot">
  <link name="base_link">
    <visual>
      <geometry><box size="0.5 0.3 0.1"/></geometry>
    </visual>
  </link>
  <link name="arm_link">
    <visual>
      <geometry><cylinder radius="0.05" length="0.4"/></geometry>
    </visual>
  </link>
  <joint name="base_to_arm" type="revolute">
    <parent link="base_link"/>
    <child link="arm_link"/>
    <origin xyz="0.2 0 0.05"/>
    <axis xyz="0 1 0"/>
    <limit lower="-1.57" upper="1.57" effort="10" velocity="1.0"/>
  </joint>
</robot>
