<?xml version="1.0"?>
<robot name="physics_bot">

  <!-- 底座 link -->
  <link name="base_link">
    <visual>
      <geometry>
        <box size="1.0 0.5 0.3"/>
      </geometry>
      <material name="blue">
        <color rgba="0 0 1 1"/>
      </material>
    </visual>

    <collision>
      <geometry>
        <box size="1.0 0.5 0.3"/>
      </geometry>
    </collision>

    <inertial>
      <mass value="5.0"/>
      <origin xyz="0 0 0" rpy="0 0 0"/>
      <inertia ixx="0.1354" ixy="0" ixz="0"
               iyy="0.4521" iyz="0" izz="0.5417"/>
    </inertial>
  </link>

  <!-- 轮子 link -->
  <link name="wheel">
    <visual>
      <geometry>
        <cylinder radius="0.1" length="0.05"/>
      </geometry>
      <material name="grey">
        <color rgba="0.5 0.5 0.5 1"/>
      </material>
    </visual>

    <collision>
      <geometry>
        <cylinder radius="0.1" length="0.05"/>
      </geometry>
    </collision>

    <inertial>
      <mass value="0.5"/>
      <origin xyz="0 0 0" rpy="0 0 0"/>
      <inertia ixx="0.0005" ixy="0" ixz="0"
               iyy="0.0005" iyz="0" izz="0.0005"/>
    </inertial>
  </link>

  <!-- 底座到轮子的连续旋转关节 -->
  <joint name="base_to_wheel" type="continuous">
    <parent link="base_link"/>
    <child link="wheel"/>
    <origin xyz="0.3 0.3 -0.15" rpy="1.5708 0 0"/>
    <axis xyz="0 0 1"/>
  </joint>

</robot>
